Workbook

Sheet Valuation_Summary
C2: Company Name: | D2: Name | E2: Compass Group
C3: Ticker: | D3: Name | E3: CPG
C4: Valuation Date: | D4: Date | E4: 46241
C5: Last Historical Year: | D5: Date | E5: 45930
C6: Current Share Price: | D6: $ | E6: 31.71
C7: Status: | E7: Overvalued
C10: Headline KPIs | AA10: =TEXT(ABS(DCF!J29), "0.0%") & IF(DCF!J29<0, " Discount to Current", " Premium to Current") -> 10.8% Discount to Current
AA11: =TEXT(ABS((Public_Comps!H41/Public_Comps!H37)-1), "0.0%") & " Premium to Peers" -> 55.1% Premium to Peers
AA12: =TEXT(Public_Comps!H41, "0.0") & "x vs. " & TEXT(Public_Comps!H37, "0.0") & "x" -> 13.9x vs. 9.0x
AA13: =TEXT(LBO!H294, "0.0%") & " IRR / " & TEXT(LBO!H300, "0.0") & "x MoIC" -> 4.9% IRR / 1.3x MoIC
AD15: Min | AE15: 25th | AF15: Median | AG15: 75th | AH15: Max | AI15: Min Point | AJ15: 25th Point | AK15: Median Point | AL15: 75th Point | AM15: Max Point
AA17: DCF Perpetuity Growth Rate Method: | AD17: =DCF!O109 -> 18.118906 | AE17: =DCF!M107 -> 20.41064 | AF17: =DCF!J104 -> 24.97781 | AG17: =DCF!G101 -> 31.793167 | AH17: =DCF!E99 -> 39.10368 | AI17: =AD17 -> 18.118906 | AJ17: =AE17-AD17 -> 2.2917339 | AK17: =AF17-AE17 -> 4.5671704 | AL17: =AG17-AF17 -> 6.8153566 | AM17: =AH17-AG17 -> 7.3105132
AA18: DCF Multiple Method: | AD18: =DCF!O94 -> 23.051381 | AE18: =DCF!M91 -> 25.307054 | AF18: =DCF!J88 -> 27.991631 | AG18: =DCF!G86 -> 30.233767 | AH18: =DCF!E84 -> 32.212554 | AI18: =AD18 -> 23.051381 | AJ18: =AE18-AD18 -> 2.2556727 | AK18: =AF18-AE18 -> 2.6845774 | AL18: =AG18-AF18 -> 2.2421356 | AM18: =AH18-AG18 -> 1.9787871
AA20: LBO: | AD20: =LBO!E305 -> 18 | AE20: =LBO!F305 -> 19.5 | AF20: =LBO!G305 -> 21 | AG20: =LBO!H305 -> 22.5 | AH20: =LBO!I305 -> 24 | AI20: =AD20 -> 18 | AJ20: =AE20-AD20 -> 1.5 | AK20: =AF20-AE20 -> 1.5 | AL20: =AG20-AF20 -> 1.5 | AM20: =AH20-AG20 -> 1.5
AA22: =Public_Comps!B55 -> FY 26 P / E: | AD22: =Public_Comps!M55 -> 17.797362 | AE22: =Public_Comps!L55 -> 19.278951 | AF22: =Public_Comps!K55 -> 33.341245 | AG22: =Public_Comps!J55 -> 36.61241 | AH22: =Public_Comps!I55 -> 39.747279 | AI22: =AD22 -> 17.797362 | AJ22: =AE22-AD22 -> 1.4815892 | AK22: =AF22-AE22 -> 14.062294 | AL22: =AG22-AF22 -> 3.2711649 | AM22: =AH22-AG22 -> 3.1348683
C23: Valuation Output Summary: | AA23: =Public_Comps!B52 -> FY26 TEV / EBITDA: | AD23: =Public_Comps!M52 -> 8.2345367 | AE23: =Public_Comps!L52 -> 8.9668628 | AF23: =Public_Comps!K52 -> 19.184273 | AG23: =Public_Comps!J52 -> 20.267634 | AH23: =Public_Comps!I52 -> 28.745832 | AI23: =AD23 -> 8.2345367 | AJ23: =AE23-AD23 -> 0.73232612 | AK23: =AF23-AE23 -> 10.21741 | AL23: =AG23-AF23 -> 1.0833614 | AM23: =AH23-AG23 -> 8.4781979
AA25: Current Share Price | AD25: =$E$6 -> 31.71 | AE25: =$E$6 -> 31.71 | AF25: =$E$6 -> 31.71 | AG25: =$E$6 -> 31.71 | AH25: =$E$6 -> 31.71 | AI25: 1000 | AJ25: 0 | AK25: =$AJ$25 -> 0 | AL25: =$AJ$25 -> 0 | AM25: =$AJ$25 -> 0
C59: Valuation Methodology | D59: Low ($) | E59: High ($) | F59: Median ($) | G59: Implied TEV ($M) | H59: vs. Spot | I59: Range Parameters
C60: Comps: FY26 EV/EBITDA | D60: =AE23 -> 8.9668628 | E60: =AG23 -> 20.267634 | F60: =AF23 -> 19.184273 | G60: =F60*DCF!$E$9+SUM(DCF!$E$14:$E$19) -> 40565.927 | H60: =F60/$E$6-1 -> -0.39500875 | I60: 25th – 75th Peer Percentile
C61: Comps: FY26 P/E | D61: =AE22 -> 19.278951 | E61: =AG22 -> 36.61241 | F61: =AF22 -> 33.341245 | G61: =F61*DCF!$E$9+SUM(DCF!$E$14:$E$19) -> 65836.123 | H61: =F61/$E$6-1 -> 0.051442616 | I61: 25th – 75th Peer Percentile
C62: LBO: Ability to Pay (15-25% IRR) | D62: =AE20 -> 19.5 | E62: =AG20 -> 22.5 | F62: =AF20 -> 21 | G62: =F62*DCF!$E$9+SUM(DCF!$E$14:$E$19) -> 43807 | H62: =F62/$E$6-1 -> -0.33774834 | I62: Required 25.0% – 15.0% IRR
C63: DCF: Multiple Method | D63: =AE18 -> 25.307054 | E63: =AG18 -> 30.233767 | F63: =AF18 -> 27.991631 | G63: =F63*DCF!$E$9+SUM(DCF!$E$14:$E$19) -> 56287.061 | H63: =F63/$E$6-1 -> -0.11726172 | I63: 9.0x – 11.5x EBITDA Multiple
C64: DCF: Perpetuity Growth | D64: =AE17 -> 20.41064 | E64: =AG17 -> 31.793167 | F64: =AF17 -> 24.97781 | G64: =F64*DCF!$E$9+SUM(DCF!$E$14:$E$19) -> 50907.391 | H64: =F64/$E$6-1 -> -0.21230495 | I64: 3.0% – 4.0% Terminal Growth
C65: Current Share Price | D65: =$E$6 -> 31.71 | E65: =$E$6 -> 31.71 | F65: =$E$6 -> 31.71 | G65: =F65*DCF!$E$9+SUM(DCF!$E$14:$E$19) -> 62924.35 | H65: 0 | I65: Spot Price as of Valuation Date
C69: Core Model Assumptions:
C71: Operating Assumptions: | E71: DCF Assumptions: | H71: LBO Assumptions:
C72: ="5-Yr Revenue Growth: "&TEXT('3_Statment_model'!L9,"0.0%")&" - "&TEXT('3_Statment_model'!H9,"0.0%")&" YoY" -> 5-Yr Revenue Growth: 6.6% - 8.0% YoY | E72: ="Calculated WACC: "&TEXT(DCF!E11,"0.0%") -> Calculated WACC: 8.0% | H72: ="Offer Premium: "&TEXT(LBO!E7,"0.0%") -> Offer Premium: 25.0%
C73: ="Direct Operating Costs: "&TEXT(('3_Statment_model'!J17+'3_Statment_model'!H15),"0.0%") & " of Rev" -> Direct Operating Costs: 90.6% of Rev | E73: ="FCF Terminal Growth Rate: "&TEXT(DCF!O8,"0.0%") -> FCF Terminal Growth Rate: 3.0% | H73: ="Entry Valuation: "&TEXT(LBO!E25,"0.0x")&" TEV / EBITDA" -> Entry Valuation: 17.2x TEV / EBITDA
C74: ="Effective Tax Rate: "&TEXT('3_Statment_model'!H21,"0.0%") -> Effective Tax Rate: 27.7% | E74: ="Terminal EBITDA Multiple: "&TEXT(DCF!J6,"0.0x") -> Terminal EBITDA Multiple: 11.0x | H74: ="Entry Leverage: "&TEXT(LBO!K240,"0.0x")&" Debt / EBITDA" -> Entry Leverage: 6.3x Debt / EBITDA
C75: ="CapEx Requirement: ~"&TEXT('3_Statment_model'!J233,"0.0%") & " of Rev" -> CapEx Requirement: ~3.0% of Rev | E75: ="Unlevered Beta: "&TEXT(DCF!E69,"0.00") -> Unlevered Beta: 0.69 | H75: ="Weighted Debt Cost: "&TEXT((LBO!K173*LBO!D37+LBO!D38*LBO!K174+LBO!K175*LBO!D39)/LBO!K230,"0.0%") -> Weighted Debt Cost: 7.7%
C76: ="NWC Intensity: ~"&TEXT('3_Statment_model'!J234,"0.0%") & " of Rev" -> NWC Intensity: ~35.6% of Rev | E76: ="Risk-Free Rate: "&TEXT(DCF!D52,"0.0%") -> Risk-Free Rate: 4.9% | H76: ="Base Scenario Exit Multiple (FY30): "&TEXT(LBO!N29-1,"0.0x") -> Base Scenario Exit Multiple (FY30): 14.0x
C80: Investment Thesis:

Sheet DCF
B3: DCF Output: | D3: Units:
C5: Company Name: | D5: Name | E5: =Valuation_Summary!E2 -> Compass Group | G5: Terminal Value - Multiples Method: | L5: Terminal Value - Perpetuity Growth Method:
C6: Last Historical Year: | D6: Date | E6: =Valuation_Summary!E5 -> 45930 | G6: Terminal EBITDA Multiple: | J6: 11 | L6: Expected Long-Term Nominal GDP Growth: | O6: 0.04
G7: Projected FY30 EBITDA: | J7: ='3_Statment_model'!L226 -> 6199.9658
C8: Current Share Price: | D8: $ | E8: =Valuation_Summary!E6 -> 31.71 | L8: Baseline Terminal FCF Growth Rate: | O8: 0.03
C9: Diluted Shares Outstanding: | D9: M Shares | E9: 1785 | G9: Baseline Terminal Value: | J9: =J6*J7 -> 68199.624 | L9: Baseline Terminal Value: | O9: =L48*(1+O8)/(E11-O8) -> 63503.263
G10: Implied Terminal FCF Growth Rate: | J10: =(J9*E11-L48)/(J9+L48) -> 0.033311224 | L10: Implied Terminal EBITDA Multiple: | O10: =O9/J7 -> 10.242518
C11: Discount Rate (WACC) | D11: % | E11: =$F$77 -> 0.080270171
G12: (+) PV of Terminal Value: | J12: =J9/(1+$E$11)^5 -> 46357.506 | L12: (+) PV of Terminal Value: | O12: =O9/(1+$E$11)^5 -> 43165.236
C13: Current Equity Value: | D13: $ M | E13: =$E$9*$E$8 -> 56602.35 | G13: (+) PV of UFCFs: | J13: =NPV($E$11,$H$48:$L$48) -> 10469.674 | L13: (+) PV of UFCFs: | O13: =NPV($E$11,$H$48:$L$48) -> 10469.674
C14: (-) Cash & Investments: | D14: $ M | E14: =-'3_Statment_model'!$G$158 -> -575 | G14: Implied Enterprise Value: | J14: =SUM(J12:J13) -> 56827.18 | L14: Implied Enterprise Value: | O14: =SUM(O12:O13) -> 53634.91
C15: (+) Debt: | D15: $ M | E15: =-'3_Statment_model'!$G$165-'3_Statment_model'!$G$172 -> 5426
C16: (+) Preferred Stock: | D16: $ M | E16: 0 | G16: % of Implied TEV from Terminal Value: | J16: =J12/J14 -> 0.81576291 | L16: % of Implied TEV from Terminal Value: | O16: =O12/O14 -> 0.8047974
C17: (+) Leases: | D17: $ M | E17: =-'3_Statment_model'!$G$166-'3_Statment_model'!$G$173 -> 1566
C18: (+) Noncontrolling Interests: | D18: $ M | E18: ='3_Statment_model'!$G$183 -> 107 | G18: (+) Cash & Investments: | J18: =-E14 -> 575 | L18: (+) Cash & Investments: | O18: =-E14 -> 575
C19: (-) Net Pension Asset: | D19: $ M | E19: -202 | G19: (-) Debt: | J19: =-E15 -> -5426 | L19: (-) Debt: | O19: =-E15 -> -5426
C20: Current Enterprise Value: | D20: $ M | E20: =SUM(E13:E19) -> 62924.35 | G20: (-) Preferred Stock: | J20: =-E16 -> 0 | L20: (-) Preferred Stock: | O20: =-E16 -> 0
G21: (-) Leases: | J21: =-E17 -> -1566 | L21: (-) Leases: | O21: =-E17 -> -1566
G22: (-) Noncontrolling Interests: | J22: =-E18 -> -107 | L22: (-) Noncontrolling Interests: | O22: =-E18 -> -107
G23: (+) Net Pension Asset: | J23: =-E19 -> 202 | L23: (+) Net Pension Asset: | O23: =-E19 -> 202
G24: Implied Equity Value: | J24: =SUM(J14,J18:J23) -> 50505.18 | L24: Implied Equity Value: | O24: =SUM(O14,O18:O23) -> 47312.91
G26: Diluted Shares Outstanding: | J26: =E9 -> 1785 | L26: Diluted Shares Outstanding: | O26: =E9 -> 1785
G28: Implied Share Price from DCF: | J28: =J24/J26 -> 28.294218 | L28: Implied Share Price from DCF: | O28: =O24/O26 -> 26.505832
G29: Premium / (Discount) to Current: | J29: =(J28-$E$8)/$E$8 -> -0.10771939 | L29: Premium / (Discount) to Current: | O29: =(O28-$E$8)/$E$8 -> -0.16411757
F31: Historical: | J31: Projected:
B32: Free Cash Flow Projections: | D32: Units: | E32: =EOMONTH(F32,-12) -> 45199 | F32: =EOMONTH(G32,-12) -> 45565 | G32: =E6 -> 45930 | H32: =EOMONTH(G32,12) -> 46295 | I32: =EOMONTH(H32,12) -> 46660 | J32: =EOMONTH(I32,12) -> 47026 | K32: =EOMONTH(J32,12) -> 47391 | L32: =EOMONTH(K32,12) -> 47756
C33: ='3_Statment_model'!C127 -> Revenue: | D33: ='3_Statment_model'!D127 -> $M | E33: ='3_Statment_model'!E127 -> 37907 | F33: ='3_Statment_model'!F127 -> 42002 | G33: ='3_Statment_model'!G127 -> 46070 | H33: ='3_Statment_model'!H127 -> 49755.6 | I33: ='3_Statment_model'!I127 -> 53561.903 | J33: ='3_Statment_model'!J127 -> 57471.922 | ... L33: ='3_Statment_model'!L127 -> 65522.992
C34: ='3_Statment_model'!C128 -> (-) Direct Costs: | D34: ='3_Statment_model'!D128 -> $M | E34: ='3_Statment_model'!E128 -> -12254 | F34: ='3_Statment_model'!F128 -> -13293 | G34: ='3_Statment_model'!G128 -> -14212 | H34: ='3_Statment_model'!H128 -> -15225.214 | I34: ='3_Statment_model'!I128 -> -16282.819 | J34: ='3_Statment_model'!J128 -> -17356.521 | ... L34: ='3_Statment_model'!L128 -> -19656.897
C35: ='3_Statment_model'!C129 -> (-) SG&A: | D35: ='3_Statment_model'!D129 -> $M | E35: ='3_Statment_model'!E129 -> -22175 | F35: ='3_Statment_model'!F129 -> -24711 | G35: ='3_Statment_model'!G129 -> -27373 | H35: ='3_Statment_model'!H129 -> -29654.338 | I35: ='3_Statment_model'!I129 -> -32030.018 | J35: ='3_Statment_model'!J129 -> -34483.153 | ... L35: ='3_Statment_model'!L129 -> -39313.795
C36: ='3_Statment_model'!C130 -> (-) Depreciation and Amortisation: | D36: ='3_Statment_model'!D130 -> $M | E36: ='3_Statment_model'!E130 -> -952 | F36: ='3_Statment_model'!F130 -> -1050 | G36: ='3_Statment_model'!G130 -> -1190 | H36: ='3_Statment_model'!H130 -> -1355.043 | I36: ='3_Statment_model'!I130 -> -1416.4544 | J36: ='3_Statment_model'!J130 -> -1490.9434 | ... L36: ='3_Statment_model'!L130 -> -1672.5334
C37: ='3_Statment_model'!C131 -> (-) Restructuring / Integration: | D37: ='3_Statment_model'!D131 -> $M | E37: ='3_Statment_model'!E131 -> -281 | F37: ='3_Statment_model'!F131 -> -408 | G37: ='3_Statment_model'!G131 -> -368 | H37: ='3_Statment_model'!H131 -> -352.33333 | I37: ='3_Statment_model'!I131 -> -352.33333 | J37: ='3_Statment_model'!J131 -> -352.33333 | ... L37: ='3_Statment_model'!L131 -> -352.33333
C38: ='3_Statment_model'!C132 -> (+) Share of Results of Joint Ventures and Associates: | D38: ='3_Statment_model'!D132 -> $M | E38: ='3_Statment_model'!E132 -> 68 | F38: ='3_Statment_model'!F132 -> 44 | G38: ='3_Statment_model'!G132 -> 37 | H38: ='3_Statment_model'!H132 -> 0 | I38: ='3_Statment_model'!I132 -> 0 | J38: ='3_Statment_model'!J132 -> 0 | ... L38: ='3_Statment_model'!L132 -> 0
C39: ='3_Statment_model'!C133 -> Operating Income (EBIT): | D39: ='3_Statment_model'!D133 -> $M | E39: =SUM(E33:E38) -> 2313 | F39: =SUM(F33:F38) -> 2584 | G39: =SUM(G33:G38) -> 2964 | H39: =SUM(H33:H38) -> 3168.6725 | I39: =SUM(I33:I38) -> 3480.2788 | J39: =SUM(J33:J38) -> 3788.9716 | K39: =SUM(K33:K38) -> 4217.6271 | L39: =SUM(L33:L38) -> 4527.4324
C41: (-) Tax Expense: | D41: ='3_Statment_model'!D135 -> $M | E41: =-E39*'3_Statment_model'!E21 -> -568.23818 | F41: =-F39*'3_Statment_model'!F21 -> -806.8716 | G41: =-G39*'3_Statment_model'!G21 -> -807.52941 | H41: =-H39*'3_Statment_model'!H21 -> -877.06122 | I41: =-I39*'3_Statment_model'!I21 -> -963.31116 | J41: =-J39*'3_Statment_model'!J21 -> -1048.7547 | K41: =-K39*'3_Statment_model'!K21 -> -1167.4028 | L41: =-L39*'3_Statment_model'!L21 -> -1253.1543
C42: Net Operating Profit After Taxes (NOPAT): | D42: ='3_Statment_model'!D136 -> $M | E42: =SUM(E39:E41) -> 1744.7618 | F42: =SUM(F39:F41) -> 1777.1284 | G42: =SUM(G39:G41) -> 2156.4706 | H42: =SUM(H39:H41) -> 2291.6113 | I42: =SUM(I39:I41) -> 2516.9676 | J42: =SUM(J39:J41) -> 2740.217 | K42: =SUM(K39:K41) -> 3050.2243 | L42: =SUM(L39:L41) -> 3274.2782
C44: (+) Depreciation and Amortisation: | D44: ='3_Statment_model'!D137 -> $M | E44: =SUM('3_Statment_model'!E191:E192) -> 1018 | F44: =SUM('3_Statment_model'!F191:F192) -> 1144 | G44: =SUM('3_Statment_model'!G191:G192) -> 1302 | H44: =SUM('3_Statment_model'!H191:H192) -> 1355.043 | I44: =SUM('3_Statment_model'!I191:I192) -> 1416.4544 | J44: =SUM('3_Statment_model'!J191:J192) -> 1490.9434 | K44: =SUM('3_Statment_model'!K191:K192) -> 1576.6617 | L44: =SUM('3_Statment_model'!L191:L192) -> 1672.5334
C45: (+/-) Change in Working Capital: | D45: ='3_Statment_model'!D138 -> $M | E45: ='3_Statment_model'!E194 -> -120 | F45: ='3_Statment_model'!F194 -> 186 | G45: ='3_Statment_model'!G194 -> -40 | H45: ='3_Statment_model'!H194 -> 40.169327 | I45: ='3_Statment_model'!I194 -> 101.37952 | J45: ='3_Statment_model'!J194 -> 92.823283 | K45: ='3_Statment_model'!K194 -> 94.711764 | L45: ='3_Statment_model'!L194 -> 157.53166
C46: (-) Net CapEx | D46: ='3_Statment_model'!D140 -> $M | E46: ='3_Statment_model'!E198 -> -1010 | F46: ='3_Statment_model'!F198 -> -1328 | G46: ='3_Statment_model'!G198 -> -1317 | H46: ='3_Statment_model'!H198 -> -1440.4019 | I46: ='3_Statment_model'!I198 -> -1574.72 | J46: ='3_Statment_model'!J198 -> -1712.6633 | K46: ='3_Statment_model'!K198 -> -1856.2799 | L46: ='3_Statment_model'!L198 -> -2005.0035
C48: Unlevered Free Cash Flow: | D48: ='3_Statment_model'!D142 -> $M | E48: =SUM(E42:E46) -> 1632.7618 | F48: =SUM(F42:F46) -> 1779.1284 | G48: =SUM(G42:G46) -> 2101.4706 | H48: =SUM(H42:H46) -> 2246.4217 | I48: =SUM(I42:I46) -> 2460.0816 | J48: =SUM(J42:J46) -> 2611.3204 | K48: =SUM(K42:K46) -> 2865.3178 | L48: =SUM(L42:L46) -> 3099.3397
B51: WACC Calculation:
...

Sheet 3_Statment_model
C2: Company Name: | E2: =Valuation_Summary!E2 -> Compass Group
C3: Last Historical Year: | E3: =Valuation_Summary!E5 -> 45930
F5: Historical: | J5: Projected:
B6: Financial Statement Drivers: | D6: Units: | E6: =EOMONTH(F6,-12) -> 45199 | F6: =EOMONTH(G6,-12) -> 45565 | G6: =$E$3 -> 45930 | H6: =EOMONTH(G6,12) -> 46295 | I6: =EOMONTH(H6,12) -> 46660 | J6: =EOMONTH(I6,12) -> 47026 | K6: =EOMONTH(J6,12) -> 47391 | L6: =EOMONTH(K6,12) -> 47756
B7: Income Statement Drivers:
C8: Revenue: | D8: $M | E8: 37907 | F8: 42002 | G8: 46070 | H8: =G8*(1+H9) -> 49755.6 | I8: =H8*(1+I9) -> 53561.903 | J8: =I8*(1+J9) -> 57471.922 | K8: =J8*(1+K9) -> 61466.221 | L8: =K8*(1+L9) -> 65522.992
C9: Revenue Growth Rate: | D9: % | F9: =(F8-E8)/E8 -> 0.10802754 | G9: =(G8-F8)/F8 -> 0.096852531 | H9: =SUM(H10:H12) -> 0.08 | I9: =SUM(I10:I12) -> 0.0765 | J9: =SUM(J10:J12) -> 0.073 | K9: =SUM(K10:K12) -> 0.0695 | L9: =SUM(L10:L12) -> 0.066
C10: Net New Business Growth: | D10: % | H10: 0.045 | I10: 0.0425 | J10: 0.04 | K10: 0.0375 | L10: 0.035
C11: Like-For-Like Growth: | D11: % | H11: 0.015 | I11: 0.014 | J11: 0.013 | K11: 0.012 | L11: 0.011
C12: Inflation: | D12: % | H12: 0.02 | I12: 0.02 | J12: 0.02 | K12: 0.02 | L12: 0.02
C14: Direct Costs: | D14: $M | E14: 12254 | F14: 13293 | G14: 14212 | H14: =H15*H8 -> 15225.214 | I14: =I15*I8 -> 16282.819 | J14: =J15*J8 -> 17356.521 | K14: =K15*K8 -> 18439.866 | L14: =L15*L8 -> 19656.897
C15: Direct Costs % Revenue: | D15: % | E15: =E14/E8 -> 0.32326483 | F15: =F14/F8 -> 0.31648493 | G15: =G14/G8 -> 0.30848708 | H15: 0.306 | I15: 0.304 | J15: 0.302 | K15: 0.3 | L15: 0.3
C16: SG&A: | D16: $M | E16: 22175 | F16: 24711 | G16: 27373 | H16: =H17*H8 -> 29654.338 | I16: =I17*I8 -> 32030.018 | J16: =J17*J8 -> 34483.153 | K16: =K17*K8 -> 36879.733 | L16: =L17*L8 -> 39313.795
C17: SG&A % Revenue: | D17: % | E17: =E16/E8 -> 0.5849843 | F17: =F16/F8 -> 0.58832913 | G17: =G16/G8 -> 0.59416106 | H17: 0.596 | I17: 0.598 | J17: 0.6 | K17: 0.6 | L17: 0.6
C18: Restructuring / Integration: | D18: $M | E18: 281 | F18: 408 | G18: 368 | H18: =AVERAGE(E18:G18) -> 352.33333 | I18: =H18 -> 352.33333 | J18: =I18 -> 352.33333 | K18: =J18 -> 352.33333 | L18: =K18 -> 352.33333
C20: Income Tax: | D20: $M | E20: 525 | F20: 642 | G20: 704 | H20: =MAX(0,H21*H138) -> 813.48766 | I20: =MAX(0,I21*I138) -> 901.93081 | J20: =MAX(0,J21*J138) -> 989.72115 | K20: =MAX(0,K21*K138) -> 1110.473 | L20: =MAX(0,L21*L138) -> 1198.2939
C21: Income Tax %: | D21: % | E21: =E20/E138 -> 0.2456715 | F21: =F20/F138 -> 0.31225681 | G21: =G20/G138 -> 0.27244582 | H21: =AVERAGE(E21:G21) -> 0.27679138 | I21: =H21 -> 0.27679138 | J21: =I21 -> 0.27679138 | K21: =J21 -> 0.27679138 | L21: =K21 -> 0.27679138
B23: Balance Sheet Drivers: | D23: =EOMONTH(E23,-12) -> 44834 | E23: =EOMONTH(F23,-12) -> 45199 | F23: =EOMONTH(G23,-12) -> 45565 | G23: =E3 -> 45930 | H23: =EOMONTH(G23,12) -> 46295 | I23: =EOMONTH(H23,12) -> 46660 | J23: =EOMONTH(I23,12) -> 47026 | K23: =EOMONTH(J23,12) -> 47391 | L23: =EOMONTH(K23,12) -> 47756
C24: Days Sales Outstanding (DSO): | D24: # Days | E24: =(E157/E127)*(E23-D23) -> 49.049252 | F24: =(F157/F127)*(F23-E23) -> 49.547069 | G24: =(G157/G127)*(G23-F23) -> 50.309312 | H24: =AVERAGE(E24:G24) -> 49.635211 | I24: =H24 -> 49.635211 | J24: =I24 -> 49.635211 | K24: =J24 -> 49.635211 | L24: =K24 -> 49.635211
C25: Days Inventory Outstanding (DIO): | D25: # Days | E25: =-(E156/E128)*(E23-D23) -> 20.612045 | F25: =-(F156/F128)*(F23-E23) -> 20.209434 | G25: =-(G156/G128)*(G23-F23) -> 21.059668 | H25: =AVERAGE(E25:G25) -> 20.627049 | I25: =H25 -> 20.627049 | J25: =I25 -> 20.627049 | K25: =J25 -> 20.627049 | L25: =K25 -> 20.627049
C26: Days Payable Outstanding (DPO): | D26: # Days | E26: =(E167/E128)*(E23-D23) -> 213.44785 | F26: =(F167/F128)*(F23-E23) -> 225.00203 | G26: =(G167/G128)*(G23-F23) -> 221.87131 | H26: =AVERAGE(E26:G26) -> 220.10706 | I26: =H26 -> 220.10706 | J26: =I26 -> 220.10706 | K26: =J26 -> 220.10706 | L26: =K26 -> 220.10706
C28: Other Current Assets % Revenue: | D28: % | E28: =E159/E127 -> 0.0035877279 | F28: =F159/F127 -> 0.010713776 | G28: =G159/G127 -> 0.0010418928 | H28: =AVERAGE(E28:G28) -> 0.0051144654 | I28: =H28 -> 0.0051144654 | J28: =I28 -> 0.0051144654 | K28: =J28 -> 0.0051144654 | L28: =K28 -> 0.0051144654
C29: Other Current Liabilities % Total Expenses: | D29: % | E29: =E168/SUM(E128:E131) -> 0.016544221 | F29: =F168/SUM(F128:F131) -> 0.020399372 | G29: =G168/SUM(G128:G131) -> 0.014950282 | H29: =AVERAGE(E29:G29) -> 0.017297958 | I29: =H29 -> 0.017297958 | J29: =I29 -> 0.017297958 | K29: =J29 -> 0.017297958 | L29: =K29 -> 0.017297958
C31: Other Long-Term Liabilities % Total Expenses: | D31: % | E31: =E174/SUM(E128:E131) -> 0.060568673 | F31: =F174/SUM(F128:F131) -> 0.064745831 | G31: =G174/SUM(G128:G131) -> 0.062095821 | H31: =AVERAGE(E31:G31) -> 0.062470108 | I31: =H31 -> 0.062470108 | J31: =I31 -> 0.062470108 | K31: =J31 -> 0.062470108 | L31: =K31 -> 0.062470108
C32: Other Long-Term Assets Growth Rate: | D32: % | F32: =(F152-E152)/E152 -> 0.031945006 | G32: =(G152-F152)/F152 -> 0.028605016 | H32: 0.027 | I32: 0.026 | J32: 0.025 | K32: 0.025 | L32: 0.025
B34: Cash Flow Statement Drivers:
C35: Dividends: | D35: $M | E35: 803 | F35: 973 | G35: 1055 | H35: =H36*H142 -> 1169.0274 | I35: =I36*I142 -> 1296.1252 | J35: =J36*J142 -> 1422.2848 | K35: =K36*K142 -> 1595.812 | L35: =L36*L142 -> 1722.0155
C36: Dividend Payout Ratio: | D36: % | E36: =E35/E190 -> 0.49813896 | F36: =F35/F190 -> 0.68811881 | G36: =G35/G190 -> 0.56117021 | H36: 0.55 | I36: 0.55 | J36: 0.55 | K36: 0.55 | L36: 0.55
C38: Stock Repurchases: | D38: $M | E38: 1167 | F38: 577 | G38: 115 | H38: =H39*H142 -> 531.3761 | I38: =I39*I142 -> 589.14781 | J38: =J39*J142 -> 646.49311 | K38: =K39*K142 -> 725.3691 | L38: =L39*L142 -> 782.73434
C39: Stock Repurchases % Net Income: | D39: % | E39: =E38/E142 -> 0.72394541 | F39: =F38/F142 -> 0.40806223 | G39: =G38/G142 -> 0.061170213 | H39: 0.25 | I39: 0.25 | J39: 0.25 | K39: 0.25 | L39: 0.25
B41: Debt Schedule:
C42: Interest Rates:
C43: Short-Term Borrowings: | D43: % | E43: 0.0412
C44: Bond Maturing in Forecast (FY26 - FY30): | D44: % | E44: 0.0244
C45: Long-Dated Bonds (Maturing After FY30): | D45: % | E45: 0.0335
C47: Short-Term Borrowings (Commercial Paper + Overdraft):
C48: Beginning Balance: | D48: $M | H48: 1043 | I48: =H51 -> 1043 | J48: =I51 -> 1043 | K48: =J51 -> 1043 | L48: =K51 -> 1043
C49: (-) Repayments: | D49: $M | H49: -337 | I49: 0 | J49: 0 | K49: 0 | L49: 0
C50: (+) Issuances: | D50: $M | H50: =-H49 -> 337 | I50: =-I49 -> 0 | J50: =-J49 -> 0 | K50: =-K49 -> 0 | L50: =-L49 -> 0
C51: Ending Balance: | D51: $M | H51: =SUM(H48:H50) -> 1043 | I51: =SUM(I48:I50) -> 1043 | J51: =SUM(J48:J50) -> 1043 | K51: =SUM(K48:K50) -> 1043 | L51: =SUM(L48:L50) -> 1043
...

Sheet Public_Comps
B9: Operating Statistics: | R9: Projected | S9: Projected
D10: Share | E10: Equity | H10: Enterprise | J10: Revenue ($M) | M10: EBITDA ($M) | P10: Net Income ($M) | R10: Revenue | S10: EBITDA | U10: EBITDA Margin
B11: Company Name: | C11: Ticker: | D11: Price ($) | E11: Value ($M) | F11: Beta | G11: Tax Rate | H11: Value ($M) | I11: TTM | J11: ='3_Statment_model'!$H$6 -> 46295 | K11: ='3_Statment_model'!$I$6 -> 46660 | L11: TTM | M11: ='3_Statment_model'!$H$6 -> 46295 | N11: ='3_Statment_model'!$I$6 -> 46660 | O11: TTM | P11: ='3_Statment_model'!$H$6 -> 46295 | Q11: ='3_Statment_model'!$I$6 -> 46660 | R11: Growth | S11: Growth | T11: TTM | U11: ='3_Statment_model'!$H$6 -> 46295 | V11: ='3_Statment_model'!$I$6 -> 46660
B12: Sodexo | C12: SW | D12: 65.87 | E12: 9580 | F12: 0.19 | G12: 0.259 | H12: 13200 | I12: 27244 | J12: 27494 | K12: 28449 | L12: 1506 | M12: 1472 | N12: 1545 | O12: 518 | P12: 287 | Q12: 365 | R12: =(K12-J12)/J12 -> 0.034734851 | S12: =(N12-M12)/M12 -> 0.049592391 | T12: =L12/I12 -> 0.055278226 | U12: =M12/J12 -> 0.053538954 | V12: =N12/K12 -> 0.054307709
B13: Aramark | C13: ARMK | D13: 56.97 | E13: 14980 | F13: 1.18 | G13: 0.257 | H13: 19620 | I13: 19414 | J13: 19970 | K13: 21412 | L13: 1345 | M13: 1540 | N13: 1724 | O13: 357 | P13: 487.2 | Q13: 637.3 | R13: =(K13-J13)/J13 -> 0.072208312 | S13: =(N13-M13)/M13 -> 0.11948052 | T13: =L13/I13 -> 0.069279901 | U13: =M13/J13 -> 0.077115674 | V13: =N13/K13 -> 0.080515599
B14: Elior Group | C14: ELIOR | D14: 2.44 | E14: 616 | F14: 1.87 | G14: 0.322 | H14: 1920 | I14: 7056 | J14: 7135 | K14: 7351 | L14: 374 | M14: 389 | N14: 443 | O14: 76 | P14: 22 | Q14: 67 | R14: =(K14-J14)/J14 -> 0.030273301 | S14: =(N14-M14)/M14 -> 0.13881748 | T14: =L14/I14 -> 0.053004535 | U14: =M14/J14 -> 0.054519972 | V14: =N14/K14 -> 0.06026391
B15: ISS Group | C15: ISS | D15: 44.32 | E15: 6950 | F15: 0.85 | G15: 0.206 | H15: 9160 | I15: 13060 | J15: 13922 | K15: 14659 | L15: 882 | M15: 975 | N15: 1036 | O15: 401 | P15: 465 | Q15: 500 | R15: =(K15-J15)/J15 -> 0.052937796 | S15: =(N15-M15)/M15 -> 0.062564103 | T15: =L15/I15 -> 0.067534456 | U15: =M15/J15 -> 0.070033041 | V15: =N15/K15 -> 0.070673307
B16: SSP Group | C16: SSPG | D16: 268.71 | E16: 2040 | F16: 0.91 | G16: 0.225 | H16: 4670 | I16: 3741 | J16: 5044 | K16: 5396 | L16: 810 | M16: 1005 | N16: 1070 | O16: -39 | P16: 126 | Q16: 151 | R16: =(K16-J16)/J16 -> 0.069785884 | S16: =(N16-M16)/M16 -> 0.064676617 | T16: =L16/I16 -> 0.21651965 | U16: =M16/J16 -> 0.19924663 | V16: =N16/K16 -> 0.19829503
B18: Maximum | D18: =MAX(D12:D16) -> 268.71 | E18: =MAX(E12:E16) -> 14980 | H18: =MAX(H12:H16) -> 19620 | I18: =MAX(I12:I16) -> 27244 | J18: =MAX(J12:J16) -> 27494 | K18: =MAX(K12:K16) -> 28449 | L18: =MAX(L12:L16) -> 1506 | M18: =MAX(M12:M16) -> 1540 | N18: =MAX(N12:N16) -> 1724 | O18: =MAX(O12:O16) -> 518 | ... V18: =MAX(V12:V16) -> 0.19829503
B19: 75th Percentile | D19: =QUARTILE(D12:D16,3) -> 65.87 | E19: =QUARTILE(E12:E16,3) -> 9580 | H19: =QUARTILE(H12:H16,3) -> 13200 | I19: =QUARTILE(I12:I16,3) -> 19414 | J19: =QUARTILE(J12:J16,3) -> 19970 | K19: =QUARTILE(K12:K16,3) -> 21412 | L19: =QUARTILE(L12:L16,3) -> 1345 | M19: =QUARTILE(M12:M16,3) -> 1472 | N19: =QUARTILE(N12:N16,3) -> 1545 | O19: =QUARTILE(O12:O16,3) -> 401 | ... V19: =QUARTILE(V12:V16,3) -> 0.080515599
B20: Median | D20: =MEDIAN(D12:D16) -> 56.97 | E20: =MEDIAN(E12:E16) -> 6950 | H20: =MEDIAN(H12:H16) -> 9160 | I20: =MEDIAN(I12:I16) -> 13060 | J20: =MEDIAN(J12:J16) -> 13922 | K20: =MEDIAN(K12:K16) -> 14659 | L20: =MEDIAN(L12:L16) -> 882 | M20: =MEDIAN(M12:M16) -> 1005 | N20: =MEDIAN(N12:N16) -> 1070 | O20: =MEDIAN(O12:O16) -> 357 | ... V20: =MEDIAN(V12:V16) -> 0.070673307
B21: 25th Percentile | D21: =QUARTILE(D12:D16,1) -> 44.32 | E21: =QUARTILE(E12:E16,1) -> 2040 | H21: =QUARTILE(H12:H16,1) -> 4670 | I21: =QUARTILE(I12:I16,1) -> 7056 | J21: =QUARTILE(J12:J16,1) -> 7135 | K21: =QUARTILE(K12:K16,1) -> 7351 | L21: =QUARTILE(L12:L16,1) -> 810 | M21: =QUARTILE(M12:M16,1) -> 975 | N21: =QUARTILE(N12:N16,1) -> 1036 | O21: =QUARTILE(O12:O16,1) -> 76 | ... V21: =QUARTILE(V12:V16,1) -> 0.06026391
B22: Minimum | D22: =MIN(D12:D16) -> 2.44 | E22: =MIN(E12:E16) -> 616 | H22: =MIN(H12:H16) -> 1920 | I22: =MIN(I12:I16) -> 3741 | J22: =MIN(J12:J16) -> 5044 | K22: =MIN(K12:K16) -> 5396 | L22: =MIN(L12:L16) -> 374 | M22: =MIN(M12:M16) -> 389 | N22: =MIN(N12:N16) -> 443 | O22: =MIN(O12:O16) -> -39 | ... V22: =MIN(V12:V16) -> 0.054307709
B24: Compass Group | C24: CPG | D24: =Valuation_Summary!E6 -> 31.71 | E24: =DCF!E8*DCF!E9 -> 56602.35 | F24: 0.65 | G24: ='3_Statment_model'!G21 -> 0.27244582 | H24: =DCF!E20 -> 62924.35 | I24: 48485 | J24: ='3_Statment_model'!H127 -> 49755.6 | K24: ='3_Statment_model'!I127 -> 53561.903 | L24: 4473 | M24: ='3_Statment_model'!H226 -> 4523.7155 | N24: ='3_Statment_model'!I226 -> 4896.7332 | O24: 2018 | P24: ='3_Statment_model'!H142 -> 2125.5044 | Q24: ='3_Statment_model'!I142 -> 2356.5913 | R24: =(K24-J24)/J24 -> 0.0765 | S24: =(N24-M24)/M24 -> 0.082458266 | T24: =L24/I24 -> 0.092255337 | U24: =M24/J24 -> 0.09091872 | V24: =N24/K24 -> 0.091421942
B26: Valuation Statistics: | E26: Enterprise Value / | H26: Enterprise Value /
E27: Revenue | H27: EBITDA | K27: P/E
B28: Company Name: | C28: Ticker: | D28: TTM | E28: ='3_Statment_model'!$H$6 -> 46295 | F28: ='3_Statment_model'!$I$6 -> 46660 | G28: TTM | H28: ='3_Statment_model'!$H$6 -> 46295 | I28: ='3_Statment_model'!$I$6 -> 46660 | J28: TTM | K28: ='3_Statment_model'!$H$6 -> 46295 | L28: ='3_Statment_model'!$I$6 -> 46660
B29: =B12 -> Sodexo | C29: =C12 -> SW | D29: =IF($H12/I12<0,"NM",$H12/I12) -> 0.48451035 | E29: =IF($H12/J12<0,"NM",$H12/J12) -> 0.48010475 | F29: =IF($H12/K12<0,"NM",$H12/K12) -> 0.46398819 | G29: =IF($H12/L12<0,"NM",$H12/L12) -> 8.7649402 | H29: =IF($H12/M12<0,"NM",$H12/M12) -> 8.9673913 | I29: =IF($H12/N12<0,"NM",$H12/N12) -> 8.5436893 | J29: =IF($E12/O12<0,"NM",$E12/O12) -> 18.494208 | K29: =IF($E12/P12<0,"NM",$E12/P12) -> 33.379791 | L29: =IF($E12/Q12<0,"NM",$E12/Q12) -> 26.246575
B30: =B13 -> Aramark | C30: =C13 -> ARMK | D30: =IF($H13/I13<0,"NM",$H13/I13) -> 1.0106109 | E30: =IF($H13/J13<0,"NM",$H13/J13) -> 0.98247371 | F30: =IF($H13/K13<0,"NM",$H13/K13) -> 0.91630861 | G30: =IF($H13/L13<0,"NM",$H13/L13) -> 14.587361 | H30: =IF($H13/M13<0,"NM",$H13/M13) -> 12.74026 | I30: =IF($H13/N13<0,"NM",$H13/N13) -> 11.38051 | J30: =IF($E13/O13<0,"NM",$E13/O13) -> 41.960784 | K30: =IF($E13/P13<0,"NM",$E13/P13) -> 30.747126 | L30: =IF($E13/Q13<0,"NM",$E13/Q13) -> 23.505413
B31: =B14 -> Elior Group | C31: =C14 -> ELIOR | D31: =IF($H14/I14<0,"NM",$H14/I14) -> 0.27210884 | E31: =IF($H14/J14<0,"NM",$H14/J14) -> 0.26909601 | F31: =IF($H14/K14<0,"NM",$H14/K14) -> 0.26118895 | G31: =IF($H14/L14<0,"NM",$H14/L14) -> 5.1336898 | H31: =IF($H14/M14<0,"NM",$H14/M14) -> 4.9357326 | I31: =IF($H14/N14<0,"NM",$H14/N14) -> 4.3340858 | J31: =IF($E14/O14<0,"NM",$E14/O14) -> 8.1052632 | K31: =IF($E14/P14<0,"NM",$E14/P14) -> 28 | L31: =IF($E14/Q14<0,"NM",$E14/Q14) -> 9.1940299
B32: =B15 -> ISS Group | C32: =C15 -> ISS | D32: =IF($H15/I15<0,"NM",$H15/I15) -> 0.70137825 | E32: =IF($H15/J15<0,"NM",$H15/J15) -> 0.65795144 | F32: =IF($H15/K15<0,"NM",$H15/K15) -> 0.62487209 | G32: =IF($H15/L15<0,"NM",$H15/L15) -> 10.385488 | H32: =IF($H15/M15<0,"NM",$H15/M15) -> 9.3948718 | I32: =IF($H15/N15<0,"NM",$H15/N15) -> 8.8416988 | J32: =IF($E15/O15<0,"NM",$E15/O15) -> 17.331671 | K32: =IF($E15/P15<0,"NM",$E15/P15) -> 14.946237 | L32: =IF($E15/Q15<0,"NM",$E15/Q15) -> 13.9
B33: =B16 -> SSP Group | C33: =C16 -> SSPG | D33: =IF($H16/I16<0,"NM",$H16/I16) -> 1.2483293 | E33: =IF($H16/J16<0,"NM",$H16/J16) -> 0.9258525 | F33: =IF($H16/K16<0,"NM",$H16/K16) -> 0.86545589 | G33: =IF($H16/L16<0,"NM",$H16/L16) -> 5.7654321 | H33: =IF($H16/M16<0,"NM",$H16/M16) -> 4.6467662 | I33: =IF($H16/N16<0,"NM",$H16/N16) -> 4.364486 | J33: =IF($E16/O16<0,"NM",$E16/O16) -> NM | K33: =IF($E16/P16<0,"NM",$E16/P16) -> 16.190476 | L33: =IF($E16/Q16<0,"NM",$E16/Q16) -> 13.509934
B35: Maximum | D35: =MAX(D29:D33) -> 1.2483293 | E35: =MAX(E29:E33) -> 0.98247371 | F35: =MAX(F29:F33) -> 0.91630861 | G35: =MAX(G29:G33) -> 14.587361 | H35: =MAX(H29:H33) -> 12.74026 | I35: =MAX(I29:I33) -> 11.38051 | J35: =MAX(J29:J33) -> 41.960784 | K35: =MAX(K29:K33) -> 33.379791 | L35: =MAX(L29:L33) -> 26.246575
B36: 75th Percentile | D36: =QUARTILE(D29:D33,3) -> 1.0106109 | E36: =QUARTILE(E29:E33,3) -> 0.9258525 | F36: =QUARTILE(F29:F33,3) -> 0.86545589 | G36: =QUARTILE(G29:G33,3) -> 10.385488 | H36: =QUARTILE(H29:H33,3) -> 9.3948718 | I36: =QUARTILE(I29:I33,3) -> 8.8416988 | J36: =QUARTILE(J29:J33,3) -> 24.360852 | K36: =QUARTILE(K29:K33,3) -> 30.747126 | L36: =QUARTILE(L29:L33,3) -> 23.505413
B37: Median | D37: =MEDIAN(D29:D33) -> 0.70137825 | E37: =MEDIAN(E29:E33) -> 0.65795144 | F37: =MEDIAN(F29:F33) -> 0.62487209 | G37: =MEDIAN(G29:G33) -> 8.7649402 | H37: =MEDIAN(H29:H33) -> 8.9673913 | I37: =MEDIAN(I29:I33) -> 8.5436893 | J37: =MEDIAN(J29:J33) -> 17.91294 | K37: =MEDIAN(K29:K33) -> 28 | L37: =MEDIAN(L29:L33) -> 13.9
B38: 25th Percentile | D38: =QUARTILE(D29:D33,1) -> 0.48451035 | E38: =QUARTILE(E29:E33,1) -> 0.48010475 | F38: =QUARTILE(F29:F33,1) -> 0.46398819 | G38: =QUARTILE(G29:G33,1) -> 5.7654321 | H38: =QUARTILE(H29:H33,1) -> 4.9357326 | I38: =QUARTILE(I29:I33,1) -> 4.364486 | J38: =QUARTILE(J29:J33,1) -> 15.025069 | K38: =QUARTILE(K29:K33,1) -> 16.190476 | L38: =QUARTILE(L29:L33,1) -> 13.509934
B39: Minimum | D39: =MIN(D29:D33) -> 0.27210884 | E39: =MIN(E29:E33) -> 0.26909601 | F39: =MIN(F29:F33) -> 0.26118895 | G39: =MIN(G29:G33) -> 5.1336898 | H39: =MIN(H29:H33) -> 4.6467662 | I39: =MIN(I29:I33) -> 4.3340858 | J39: =MIN(J29:J33) -> 8.1052632 | K39: =MIN(K29:K33) -> 14.946237 | L39: =MIN(L29:L33) -> 9.1940299
B41: Compass Group | C41: CPG | D41: =IF($H24/I24<0,"NM",$H24/I24) -> 1.2978107 | E41: =IF($H24/J24<0,"NM",$H24/J24) -> 1.2646687 | F41: =IF($H24/K24<0,"NM",$H24/K24) -> 1.1747967 | G41: =IF($H24/L24<0,"NM",$H24/L24) -> 14.067594 | H41: =IF($H24/M24<0,"NM",$H24/M24) -> 13.909882 | I41: =IF($H24/N24<0,"NM",$H24/N24) -> 12.850271 | J41: =IF($E24/O24<0,"NM",$E24/O24) -> 28.048736 | K41: =IF($E24/P24<0,"NM",$E24/P24) -> 26.630079 | L41: =IF($E24/Q24<0,"NM",$E24/Q24) -> 24.018739
D45: 75th | F45: 25th | H45: Applicable | J45: 75th | L45: 25th
C46: Maximum | D46: Percentile | E46: Median | F46: Percentile | G46: Minimum | H46: Company | I46: Maximum | J46: Percentile | K46: Median | L46: Percentile | M46: Minimum
B47: Methodology Name | C47: Multiple | D47: Multiple | E47: Multiple | F47: Multiple | G47: Multiple | H47: Figure | I47: Multiple | J47: Multiple | K47: Multiple | L47: Multiple | M47: Multiple
B48: TTM TEV / Revenue: | C48: {=TRANSPOSE(D35:L39)} -> 1.2483293 | D48: 1.0106109 | E48: 0.70137825 | F48: 0.48451035 | G48: 0.27210884 | H48: {=TRANSPOSE(I24:Q24)} -> 48485 | I48: =((C48*$H48)-SUM($D$59:$D$64))/$D$67 -> 30.365965 | J48: =((D48*$H48)-SUM($D$59:$D$64))/$D$67 -> 23.908946 | K48: =((E48*$H48)-SUM($D$59:$D$64))/$D$67 -> 15.509426 | L48: =((F48*$H48)-SUM($D$59:$D$64))/$D$67 -> 9.6187587 | M48: =((G48*$H48)-SUM($D$59:$D$64))/$D$67 -> 3.8494102
B49: ="FY26 TEV / Revenue:" -> FY26 TEV / Revenue: | C49: 0.98247371 | D49: 0.9258525 | E49: 0.65795144 | F49: 0.48010475 | G49: 0.26909601 | H49: 49755.6 | I49: =((C49*$H49)-SUM($D$59:$D$64))/$D$67 -> 23.844016 | J49: =((D49*$H49)-SUM($D$59:$D$64))/$D$67 -> 22.26574 | K49: =((E49*$H49)-SUM($D$59:$D$64))/$D$67 -> 14.79819 | L49: =((F49*$H49)-SUM($D$59:$D$64))/$D$67 -> 9.8408403 | M49: =((G49*$H49)-SUM($D$59:$D$64))/$D$67 -> 3.9591223
B50: ="FY27 TEV / Revenue:" -> FY27 TEV / Revenue: | C50: 0.91630861 | D50: 0.86545589 | E50: 0.62487209 | F50: 0.46398819 | G50: 0.26118895 | H50: 53561.903 | I50: =((C50*$H50)-SUM($D$59:$D$64))/$D$67 -> 23.953632 | J50: =((D50*$H50)-SUM($D$59:$D$64))/$D$67 -> 22.427711 | K50: =((E50*$H50)-SUM($D$59:$D$64))/$D$67 -> 15.208593 | L50: =((F50*$H50)-SUM($D$59:$D$64))/$D$67 -> 10.381003 | M50: =((G50*$H50)-SUM($D$59:$D$64))/$D$67 -> 4.2956737
B51: TTM TEV / EBITDA: | C51: 14.587361 | D51: 10.385488 | E51: 8.7649402 | F51: 5.7654321 | G51: 5.1336898 | H51: 4473 | I51: =((C51*$H51)-SUM($D$59:$D$64))/$D$67 -> 33.012473 | J51: =((D51*$H51)-SUM($D$59:$D$64))/$D$67 -> 22.483073 | K51: =((E51*$H51)-SUM($D$59:$D$64))/$D$67 -> 18.422172 | L51: =((F51*$H51)-SUM($D$59:$D$64))/$D$67 -> 10.905758 | M51: =((G51*$H51)-SUM($D$59:$D$64))/$D$67 -> 9.3226861
B52: ="FY26 TEV / EBITDA:" -> FY26 TEV / EBITDA: | C52: 12.74026 | D52: 9.3948718 | E52: 8.9673913 | F52: 4.9357326 | G52: 4.6467662 | H52: 4523.7155 | I52: =((C52*$H52)-SUM($D$59:$D$64))/$D$67 -> 28.745832 | J52: =((D52*$H52)-SUM($D$59:$D$64))/$D$67 -> 20.267634 | K52: =((E52*$H52)-SUM($D$59:$D$64))/$D$67 -> 19.184273 | L52: =((F52*$H52)-SUM($D$59:$D$64))/$D$67 -> 8.9668628 | M52: =((G52*$H52)-SUM($D$59:$D$64))/$D$67 -> 8.2345367
B53: ="FY27 TEV / EBITDA:" -> FY27 TEV / EBITDA: | C53: 11.38051 | D53: 8.8416988 | E53: 8.5436893 | F53: 4.364486 | G53: 4.3340858 | H53: 4896.7332 | I53: =((C53*$H53)-SUM($D$59:$D$64))/$D$67 -> 27.678052 | J53: =((D53*$H53)-SUM($D$59:$D$64))/$D$67 -> 20.713412 | K53: =((E53*$H53)-SUM($D$59:$D$64))/$D$67 -> 19.895892 | L53: =((F53*$H53)-SUM($D$59:$D$64))/$D$67 -> 8.4312176 | M53: =((G53*$H53)-SUM($D$59:$D$64))/$D$67 -> 8.3478217
B54: TTM P / E: | C54: 41.960784 | D54: 24.360852 | E54: 17.91294 | F54: 15.025069 | G54: 8.1052632 | H54: 2018 | I54: =(C54*$H54)/$D$67 -> 47.438018 | J54: =(D54*$H54)/$D$67 -> 27.540728 | K54: =(E54*$H54)/$D$67 -> 20.251155 | L54: =(F54*$H54)/$D$67 -> 16.986324 | M54: =(G54*$H54)/$D$67 -> 9.1632611
B55: ="FY 26 P / E:" -> FY 26 P / E: | C55: 33.379791 | D55: 30.747126 | E55: 28 | F55: 16.190476 | G55: 14.946237 | H55: 2125.5044 | I55: =(C55*$H55)/$D$67 -> 39.747279 | J55: =(D55*$H55)/$D$67 -> 36.61241 | K55: =(E55*$H55)/$D$67 -> 33.341245 | L55: =(F55*$H55)/$D$67 -> 19.278951 | M55: =(G55*$H55)/$D$67 -> 17.797362
B56: ="FY 27 P / E:" -> FY 27 P / E: | C56: 26.246575 | D56: 23.505413 | E56: 13.9 | F56: 13.509934 | G56: 9.1940299 | H56: 2356.5913 | I56: =(C56*$H56)/$D$67 -> 34.651232 | J56: =(D56*$H56)/$D$67 -> 31.032298 | K56: =(E56*$H56)/$D$67 -> 18.351047 | L56: =(F56*$H56)/$D$67 -> 17.836074 | M56: =(G56*$H56)/$D$67 -> 12.138135
...

Sheet LBO
B2: Transaction Assumptions: | D2: Units:
C3: Company Name: | D3: Name | E3: =Valuation_Summary!E2 -> Compass Group
C4: Last Historical Year: | D4: Date | E4: =Valuation_Summary!E5 -> 45930
C6: Undisturbed Share Price: | D6: $ | E6: =Valuation_Summary!E6 -> 31.71
C7: Premium Paid: | D7: % | E7: 0.25
C8: Offer Price per Share: | D8: $ | E8: =E6*(1+E7) -> 39.6375
C10: Diluted Shares Outstanding: | D10: M Shares | E10: =DCF!E9 -> 1785
C12: Purchase Equity Value: | D12: $ M | E12: =E8*E10 -> 70752.938
C13: (-) Cash & Investments: | D13: $ M | E13: =DCF!E14 -> -575
C14: (+) Debt: | D14: $ M | E14: =DCF!E15 -> 5426
C15: (+) Preferred Stock: | D15: $ M | E15: =DCF!E16 -> 0
C16: (+) Leases: | D16: $ M | E16: =DCF!E17 -> 1566
C17: (+) Noncontrolling Interests: | D17: $ M | E17: =DCF!E18 -> 107
C18: (-) Net Pension Asset: | D18: $ M | E18: =DCF!E19 -> -202
C19: Purchase Enterprise Value: | D19: $ M | E19: =SUM(E12:E18) -> 77074.938
G20: Selected Operating Scenario: | M20: Name | N20: Base
C21: EBITDA: | D21: $ M | E21: =G67-G64 -> 4154 | G21: Management Rollover: | M21: % | N21: 0.1
C22: Purchase TEV / EBITDA Multiple: | D22: x | E22: =E19/E21 -> 18.55439 | G22: Minimum Cash Balance: | M22: $ M | N22: 300
G23: Tax Rate: | M23: % | N23: ='3_Statment_model'!H21 -> 0.27679138
C24: Normalised EBITDA: | D24: $ M | E24: =E21-G65-G66 -> 4485
C25: Normalised Purchase TEV / EBITDA Multiple: | D25: x | E25: =E19/E24 -> 17.185047 | G25: Exit Year: | M25: Date | N25: 47756
C27: Advisory Fee % Purchase Equity Value: | D27: % | E27: 0.01 | G27: Year 3 EBITDA Exit Multiple:
C28: Debt Issuance Fee %: | D28: % | E28: 0.02 | G28: Upside | M28: x | N28: 17.5
C29: Amortization Period: | D29: Years | E29: 7 | G29: Base | M29: x | N29: 15
G30: Downside | M30: x | N30: 13
C31: Legal and Other Fees: | D31: $ M | E31: 25 | G31: Selected Scenario: | M31: x | N31: =INDEX(N28:N30,MATCH(N20,$G28:$G30,0),1) -> 15
B33: Sources & Uses Schedule:
C35: Sources of Funds: | D35: $M | E35: x EBITDA | F35: % Sources | H35: Uses of Funds: | K35: $M | L35: x EBITDA
C36: Revolver: | D36: =E36*$E$24 -> 0 | E36: 0 | F36: =D36/$D$43 -> 0 | H36: Purchase Equity Value: | K36: =E12 -> 70752.938 | L36: =K36/$E$24 -> 15.77546
C37: Term Loan A: | D37: =E37*$E$24 -> 8970 | E37: 2 | F37: =D37/$D$43 -> 0.11575012 | H37: Assume/Replace Target's Debt: | K37: =-G100-G107 -> 5426 | L37: =K37/$E$24 -> 1.2098105
C38: Term Loan B: | D38: =E38*$E$24 -> 13455 | E38: 3 | F38: =D38/$D$43 -> 0.17362519 | H38: Transaction Fees: | K38: =E31+E27*E12 -> 732.52937 | L38: =K38/$E$24 -> 0.16332873
C39: Subordinated Notes: | D39: =E39*$E$24 -> 6727.5 | E39: 1.5 | F39: =D39/$D$43 -> 0.086812594 | H39: Financing Fees: | K39: =E28*SUM(D36:D39) -> 583.05 | L39: =K39/$E$24 -> 0.13
C40: Management Rollover: | D40: =N21*E12 -> 7075.2938 | E40: =D40/$E$24 -> 1.577546 | F40: =D40/$D$43 -> 0.091300572 | H40: Total Uses: | K40: =SUM(K36:K39) -> 77494.517 | L40: =SUM(L36:L39) -> 17.278599
C41: Excess Cash: | D41: =MAX(G93-N22,0) -> 275 | E41: =D41/$E$24 -> 0.061315496 | F41: =D41/$D$43 -> 0.0035486382
C42: Investor Equity: | D42: =K40-SUM(D36:D41) -> 40991.723 | E42: =D42/$E$24 -> 9.1397376 | F42: =D42/$D$43 -> 0.52896288
C43: Total Sources: | D43: =SUM(D36:D42) -> 77494.517 | E43: =SUM(E36:E42) -> 17.278599 | F43: =SUM(F36:F42) -> 1
C45: Ownership Details: | D45: $M | E45: %
C46: Management: | D46: =D40 -> 7075.2938 | E46: =D46/$D$48 -> 0.14719644
C47: Sponsor: | D47: =D42 -> 40991.723 | E47: =D47/$D$48 -> 0.85280356
C48: Total Equity: | D48: =SUM(D46:D47) -> 48067.017 | E48: =SUM(E46:E47) -> 1
...

Sheet Imported_Financial_Statements
A1: Income Statement: | F1: Balance Sheet: | K1: Statement of Cash Flows:
A3: Column1 | B3: Column2 | C3: Column3 | D3: Column4 | F3: Column1 | G3: Column2 | H3: Column3 | I3: Column4 | K3: Column1 | L3: Column2 | M3: Column3 | N3: Column4
B4: 2025-09-30 | C4: 2024-09-30 | D4: 2023-09-30 | G4: 2025-09-30 | H4: 2024-09-30 | I4: 2023-09-30 | L4: 2025-09-30 | M4: 2024-09-30 | N4: 2023-09-30
A5: Tax Effect Of Unusual Items | B5: -117151702.786378 | C5: -214520428.015564 | D5: -85362000.0 | F5: Treasury Shares Number | G5: 88102999.0 | H5: 88290717.0 | I5: 70744082.0 | K5: Free Cash Flow | L5: 2474000000.0 | M5: 2234000000.0 | N5: 1828000000.0
A6: Tax Rate For Calcs | B6: 0.272446 | C6: 0.312257 | D6: 0.246 | F6: Ordinary Shares Number | G6: 1697300978.0 | H6: 1697113260.0 | I6: 1714659895.0 | K6: Repurchase Of Capital Stock | L6: -115000000.0 | M6: -577000000.0 | N6: -1148000000.0
A7: Normalized EBITDA | B7: 4582000000.0 | C7: 4098000000.0 | D7: 3657000000.0 | F7: Share Issued | G7: 1785403977.0 | H7: 1785403977.0 | I7: 1785403977.0 | K7: Repayment Of Debt | L7: -882000000.0 | M7: -1592000000.0 | N7: -543000000.0
A8: Total Unusual Items | B8: -430000000.0 | C8: -687000000.0 | D8: -347000000.0 | F8: Net Debt | G8: 4851000000.0 | H8: 3973000000.0 | I8: 3085000000.0 | K8: Issuance Of Debt | L8: 1412000000.0 | M8: 1381000000.0 | N8: 1000000.0
A9: Total Unusual Items Excluding Goodwill | B9: -430000000.0 | C9: -687000000.0 | D9: -347000000.0 | F9: Total Debt | G9: 6992000000.0 | H9: 5911000000.0 | I9: 5267000000.0 | K9: Issuance Of Capital Stock | M9: 0.0 | N9: -19000000.0
A10: Net Income From Continuing Operation Net Minority Interest | B10: 1868000000.0 | C10: 1404000000.0 | D10: 1607000000.0 | F10: Tangible Book Value | G10: -4033000000.0 | H10: -3395000000.0 | I10: -2322000000.0 | K10: Capital Expenditure | L10: -892000000.0 | M10: -901000000.0 | N10: -708000000.0
A11: Reconciled Depreciation | B11: 852000000.0 | C11: 744000000.0 | D11: 670000000.0 | F11: Invested Capital | G11: 13079000000.0 | H11: 11425000000.0 | I11: 10377000000.0 | K11: End Cash Position | L11: 512000000.0 | M11: 593000000.0 | N11: 830000000.0
A12: Reconciled Cost Of Revenue | B12: 30677000000.0 | C12: 28076000000.0 | D12: 25567000000.0 | F12: Working Capital | G12: -2872000000.0 | H12: -2579000000.0 | I12: -2369000000.0 | K12: Other Cash Adjustment Outside Changein Cash | M12: -40000000.0
A13: EBITDA | B13: 4152000000.0 | C13: 3411000000.0 | D13: 3310000000.0 | F13: Net Tangible Assets | G13: -4033000000.0 | H13: -3395000000.0 | I13: -2322000000.0 | K13: Beginning Cash Position | L13: 593000000.0 | M13: 830000000.0 | N13: 1934000000.0
A14: EBIT | B14: 2962000000.0 | C14: 2361000000.0 | D14: 2358000000.0 | F14: Capital Lease Obligations | G14: 1566000000.0 | H14: 1315000000.0 | I14: 1153000000.0 | K14: Effect Of Exchange Rate Changes | L14: 22000000.0 | M14: 59000000.0 | N14: 169000000.0
A15: Net Interest Income | B15: -356000000.0 | C15: -277000000.0 | D15: -175000000.0 | F15: Common Stock Equity | G15: 7653000000.0 | H15: 6829000000.0 | I15: 6263000000.0 | K15: Changes In Cash | L15: -103000000.0 | M15: -296000000.0 | N15: -1273000000.0
A16: Interest Expense | B16: 378000000.0 | C16: 305000000.0 | D16: 221000000.0 | F16: Total Capitalization | G16: 12036000000.0 | H16: 10603000000.0 | I16: 9050000000.0 | K16: Financing Cash Flow | L16: -1045000000.0 | M16: -1942000000.0 | N16: -2580000000.0
A17: Interest Income | B17: 29000000.0 | C17: 30000000.0 | D17: 53000000.0 | F17: Total Equity Gross Minority Interest | G17: 7760000000.0 | H17: 6906000000.0 | I17: 6300000000.0 | K17: Net Other Financing Charges | L17: -140000000.0 | M17: 46000000.0 | N17: 147000000.0
A18: Normalized Income | B18: 2180848297.213622 | C18: 1876479571.984436 | D18: 1868638000.0 | F18: Minority Interest | G18: 107000000.0 | H18: 77000000.0 | I18: 37000000.0 | K18: Cash Dividends Paid | L18: -1047000000.0 | M18: -963000000.0 | N18: -796000000.0
A19: Net Income From Continuing And Discontinued Operation | B19: 1868000000.0 | C19: 1404000000.0 | D19: 1607000000.0 | F19: Stockholders Equity | G19: 7653000000.0 | H19: 6829000000.0 | I19: 6263000000.0 | K19: Common Stock Dividend Paid | L19: -1047000000.0 | M19: -963000000.0 | N19: -796000000.0
A20: Total Expenses | B20: 42775000000.0 | C20: 39054000000.0 | D20: 35339000000.0 | F20: Other Equity Interest | K20: Net Common Stock Issuance | L20: -115000000.0 | M20: -577000000.0 | N20: -1167000000.0
A21: Rent Expense Supplemental | C21: 192000000.0 | D21: 182000000.0 | F21: Fixed Assets Revaluation Reserve | G21: 0.0 | H21: 0.0 | I21: 14000000.0 | K21: Common Stock Payments | L21: -115000000.0 | M21: -577000000.0 | N21: -1148000000.0
A22: Total Operating Income As Reported | B22: 2964000000.0 | C22: 2584000000.0 | D22: 2245000000.0 | F22: Treasury Stock | G22: 2220000000.0 | H22: 2296000000.0 | I22: 1848000000.0 | K22: Common Stock Issuance | M22: 0.0 | N22: -19000000.0
A23: Diluted Average Shares | B23: 1699000000.0 | C23: 1707000000.0 | D23: 1745000000.0 | F23: Retained Earnings | G23: 2302000000.0 | H23: 1574000000.0 | I23: 1018000000.0 | K23: Net Issuance Payments Of Debt | L23: 530000000.0 | M23: -211000000.0 | N23: -542000000.0
A24: Basic Average Shares | B24: 1697000000.0 | C24: 1705000000.0 | D24: 1743000000.0 | F24: Additional Paid In Capital | G24: 828000000.0 | H24: 828000000.0 | I24: 828000000.0 | K24: Net Long Term Debt Issuance | L24: 530000000.0 | M24: -211000000.0 | N24: -542000000.0
A25: Diluted EPS | B25: 1.099 | C25: 0.822 | D25: 0.91873 | F25: Capital Stock | G25: 346000000.0 | H25: 346000000.0 | I25: 346000000.0 | K25: Long Term Debt Payments | L25: -882000000.0 | M25: -1592000000.0 | N25: -543000000.0
A26: Basic EPS | B26: 1.101 | C26: 0.823 | D26: 0.91995 | F26: Common Stock | G26: 346000000.0 | H26: 346000000.0 | I26: 346000000.0 | K26: Long Term Debt Issuance | L26: 1412000000.0 | M26: 1381000000.0 | N26: 1000000.0
A27: Diluted NI Availto Com Stockholders | B27: 1868000000.0 | C27: 1404000000.0 | D27: 1607000000.0 | F27: Total Liabilities Net Minority Interest | G27: 18955000000.0 | H27: 17443000000.0 | I27: 15183000000.0 | K27: Investing Cash Flow | L27: -2424000000.0 | M27: -1489000000.0 | N27: -1229000000.0
A28: Net Income Common Stockholders | B28: 1868000000.0 | C28: 1404000000.0 | D28: 1607000000.0 | F28: Total Non Current Liabilities Net Minority Interest | G28: 8290000000.0 | H28: 7371000000.0 | I28: 5863000000.0 | K28: Net Other Investing Changes | L28: -490000000.0 | M28: -508000000.0 | N28: -380000000.0
A29: Otherunder Preferred Stock Dividend | B29: 0.0 | C29: 0.0 | D29: 0.0 | F29: Other Non Current Liabilities | K29: Interest Received Cfi | L29: 37000000.0 | M29: 39000000.0 | N29: 61000000.0
A30: Net Income | B30: 1868000000.0 | C30: 1404000000.0 | D30: 1607000000.0 | F30: Derivative Product Liabilities | G30: 208000000.0 | H30: 252000000.0 | I30: 253000000.0 | K30: Dividends Received Cfi | L30: 43000000.0 | M30: 65000000.0 | N30: 60000000.0
A31: Minority Interests | B31: -12000000.0 | C31: -10000000.0 | D31: -5000000.0 | F31: Non Current Pension And Other Postretirement Benefit Plans | G31: 1395000000.0 | H31: 1274000000.0 | I31: 983000000.0 | K31: Net Investment Purchase And Sale | L31: -98000000.0 | M31: 328000000.0 | N31: 0.0
A32: Net Income Including Noncontrolling Interests | B32: 1880000000.0 | C32: 1414000000.0 | D32: 1612000000.0 | F32: Non Current Accrued Expenses | G32: 4000000.0 | H32: 9000000.0 | K32: Sale Of Investment | M32: 330000000.0 | N32: 4000000.0
A33: Net Income Continuous Operations | B33: 1880000000.0 | C33: 1414000000.0 | D33: 1612000000.0 | F33: Tradeand Other Payables Non Current | G33: 189000000.0 | H33: 175000000.0 | I33: 443000000.0 | K33: Purchase Of Investment | L33: -98000000.0 | M33: -2000000.0 | N33: -4000000.0
A34: Tax Provision | B34: 704000000.0 | C34: 642000000.0 | D34: 525000000.0 | F34: Non Current Deferred Revenue | G34: 252000000.0 | H34: 214000000.0 | K34: Net Business Purchase And Sale | L34: -1091000000.0 | M34: -568000000.0 | N34: -340000000.0
A35: Pretax Income | B35: 2584000000.0 | C35: 2056000000.0 | D35: 2137000000.0 | F35: Non Current Deferred Taxes Liabilities | G35: 276000000.0 | H35: 287000000.0 | I35: 132000000.0 | K35: Sale Of Business | L35: 166000000.0 | M35: 225000000.0 | N35: 58000000.0
A36: Special Income Charges | B36: -410000000.0 | C36: -620000000.0 | D36: -299000000.0 | F36: Long Term Debt And Capital Lease Obligation | G36: 5611000000.0 | H36: 4816000000.0 | I36: 3703000000.0 | K36: Purchase Of Business | L36: -1257000000.0 | M36: -793000000.0 | N36: -398000000.0
A37: Other Special Charges | B37: 31000000.0 | C37: 203000000.0 | D37: -24000000.0 | F37: Long Term Capital Lease Obligation | G37: 1228000000.0 | H37: 1042000000.0 | I37: 916000000.0 | K37: Net Intangibles Purchase And Sale | L37: -347000000.0 | M37: -329000000.0 | N37: -263000000.0
A38: Write Off | B38: 8000000.0 | C38: 3000000.0 | D38: 77000000.0 | F38: Long Term Debt | G38: 4383000000.0 | H38: 3774000000.0 | I38: 2787000000.0 | K38: Purchase Of Intangibles | L38: -347000000.0 | M38: -329000000.0 | N38: -263000000.0
A39: Impairment Of Capital Assets | C39: 146000000.0 | D39: 60000000.0 | F39: Long Term Provisions | G39: 355000000.0 | H39: 344000000.0 | I39: 349000000.0 | K39: Net PPE Purchase And Sale | L39: -478000000.0 | M39: -491000000.0 | N39: -367000000.0
A40: Restructuring And Mergern Acquisition | B40: 371000000.0 | C40: 414000000.0 | D40: 186000000.0 | F40: Current Liabilities | G40: 10665000000.0 | H40: 10072000000.0 | I40: 9320000000.0 | K40: Sale Of PPE | L40: 67000000.0 | M40: 81000000.0 | N40: 78000000.0
A41: Net Non Operating Interest Income Expense | B41: -356000000.0 | C41: -277000000.0 | D41: -175000000.0 | F41: Other Current Liabilities | K41: Purchase Of PPE | L41: -545000000.0 | M41: -572000000.0 | N41: -445000000.0
...
